Workbook

Sheet Employee Database
A1: EMPLOYEE PERFORMANCE & SALARY MANAGEMENT SYSTEM
A2: Confidential — HR Department | Fiscal Year 2025
A3: Emp ID | B3: Full Name | C3: Department | D3: Job Title | E3: Level | F3: Hire Date | G3: Years Exp | H3: Base Salary | I3: Bonus % | J3: Bonus Amount | K3: Total Comp | L3: Performance Rating | M3: KPI Score | N3: Attendance % | O3: Training hrs | P3: Promotion Eligible | Q3: Salary Band | R3: Status
A4: EMP0001 | B4: Jessica Davis | C4: Marketing | D4: SEO Specialist | E4: Junior | F4: 2021-11-01 | G4: 4 | H4: 47800 | I4: =IF(L4="Outstanding",0.2,IF(L4="Exceeds",0.15,IF(L4="Meets",0.08,IF(L4="Below",0.02,0)))) -> 0.2 | J4: =H4*I4 -> 9560 | K4: =H4+J4 -> 57360 | L4: Outstanding | M4: 88.3 | N4: 0.909 | O4: 54 | P4: =IF(AND(G4>=2,M4>=80,L4<>"Below"),"Yes","No") -> Yes | Q4: =IF(H4<65000,"Band 1 (Junior)",IF(H4<90000,"Band 2 (Mid)",IF(H4<130000,"Band 3 (Senior)",IF(H4<170000,"Band 4 (Lead/Mgr)","Band 5 (Director)")))) -> Band 1 (Junior) | R4: Active
A5: EMP0002 | B5: Jessica Thompson | C5: Engineering | D5: DevOps Engineer | E5: Junior | F5: 2007-04-01 | G5: 18 | H5: 57000 | I5: =IF(L5="Outstanding",0.2,IF(L5="Exceeds",0.15,IF(L5="Meets",0.08,IF(L5="Below",0.02,0)))) -> 0.02 | J5: =H5*I5 -> 1140 | K5: =H5+J5 -> 58140 | L5: Below | M5: 87.2 | N5: 0.94 | O5: 28 | P5: =IF(AND(G5>=2,M5>=80,L5<>"Below"),"Yes","No") -> No | Q5: =IF(H5<65000,"Band 1 (Junior)",IF(H5<90000,"Band 2 (Mid)",IF(H5<130000,"Band 3 (Senior)",IF(H5<170000,"Band 4 (Lead/Mgr)","Band 5 (Director)")))) -> Band 1 (Junior) | R5: Active
A6: EMP0003 | B6: Melissa Anderson | C6: HR | D6: Recruiter | E6: Junior | F6: 2018-06-01 | G6: 7 | H6: 50600 | I6: =IF(L6="Outstanding",0.2,IF(L6="Exceeds",0.15,IF(L6="Meets",0.08,IF(L6="Below",0.02,0)))) -> 0.08 | J6: =H6*I6 -> 4048 | K6: =H6+J6 -> 54648 | L6: Meets | M6: 59.6 | N6: 0.876 | O6: 44 | P6: =IF(AND(G6>=2,M6>=80,L6<>"Below"),"Yes","No") -> No | Q6: =IF(H6<65000,"Band 1 (Junior)",IF(H6<90000,"Band 2 (Mid)",IF(H6<130000,"Band 3 (Senior)",IF(H6<170000,"Band 4 (Lead/Mgr)","Band 5 (Director)")))) -> Band 1 (Junior) | R6: Active
A7: EMP0004 | B7: Rebecca Brown | C7: HR | D7: HRBP | E7: Junior | F7: 2012-02-01 | G7: 13 | H7: 64500 | I7: =IF(L7="Outstanding",0.2,IF(L7="Exceeds",0.15,IF(L7="Meets",0.08,IF(L7="Below",0.02,0)))) -> 0.2 | J7: =H7*I7 -> 12900 | K7: =H7+J7 -> 77400 | L7: Outstanding | M7: 79.8 | N7: 0.966 | O7: 46 | P7: =IF(AND(G7>=2,M7>=80,L7<>"Below"),"Yes","No") -> No | Q7: =IF(H7<65000,"Band 1 (Junior)",IF(H7<90000,"Band 2 (Mid)",IF(H7<130000,"Band 3 (Senior)",IF(H7<170000,"Band 4 (Lead/Mgr)","Band 5 (Director)")))) -> Band 1 (Junior) | R7: Active
A8: EMP0005 | B8: Maria Davis | C8: Finance | D8: Financial Analyst | E8: Director | F8: 2022-04-01 | G8: 3 | H8: 204100 | I8: =IF(L8="Outstanding",0.2,IF(L8="Exceeds",0.15,IF(L8="Meets",0.08,IF(L8="Below",0.02,0)))) -> 0.02 | J8: =H8*I8 -> 4082 | K8: =H8+J8 -> 208182 | L8: Below | M8: 94 | N8: 0.876 | O8: 46 | P8: =IF(AND(G8>=2,M8>=80,L8<>"Below"),"Yes","No") -> No | Q8: =IF(H8<65000,"Band 1 (Junior)",IF(H8<90000,"Band 2 (Mid)",IF(H8<130000,"Band 3 (Senior)",IF(H8<170000,"Band 4 (Lead/Mgr)","Band 5 (Director)")))) -> Band 5 (Director) | R8: Active
A9: EMP0006 | B9: William Williams | C9: Operations | D9: Logistics Coordinator | E9: Senior | F9: 2019-09-01 | G9: 6 | H9: 114400 | I9: =IF(L9="Outstanding",0.2,IF(L9="Exceeds",0.15,IF(L9="Meets",0.08,IF(L9="Below",0.02,0)))) -> 0.02 | J9: =H9*I9 -> 2288 | K9: =H9+J9 -> 116688 | L9: Below | M9: 87.8 | N9: 0.833 | O9: 34 | P9: =IF(AND(G9>=2,M9>=80,L9<>"Below"),"Yes","No") -> No | Q9: =IF(H9<65000,"Band 1 (Junior)",IF(H9<90000,"Band 2 (Mid)",IF(H9<130000,"Band 3 (Senior)",IF(H9<170000,"Band 4 (Lead/Mgr)","Band 5 (Director)")))) -> Band 3 (Senior) | R9: On Leave
A10: EMP0007 | B10: Maria Davis | C10: Finance | D10: Controller | E10: Director | F10: 2014-07-01 | G10: 11 | H10: 207500 | I10: =IF(L10="Outstanding",0.2,IF(L10="Exceeds",0.15,IF(L10="Meets",0.08,IF(L10="Below",0.02,0)))) -> 0.2 | J10: =H10*I10 -> 41500 | K10: =H10+J10 -> 249000 | L10: Outstanding | M10: 67 | N10: 0.842 | O10: 40 | P10: =IF(AND(G10>=2,M10>=80,L10<>"Below"),"Yes","No") -> No | Q10: =IF(H10<65000,"Band 1 (Junior)",IF(H10<90000,"Band 2 (Mid)",IF(H10<130000,"Band 3 (Senior)",IF(H10<170000,"Band 4 (Lead/Mgr)","Band 5 (Director)")))) -> Band 5 (Director) | R10: Active
A11: EMP0008 | B11: Michael Wilson | C11: Legal | D11: CLO | E11: Lead | F11: 2007-09-01 | G11: 18 | H11: 115600 | I11: =IF(L11="Outstanding",0.2,IF(L11="Exceeds",0.15,IF(L11="Meets",0.08,IF(L11="Below",0.02,0)))) -> 0.2 | J11: =H11*I11 -> 23120 | K11: =H11+J11 -> 138720 | L11: Outstanding | M11: 66.8 | N11: 0.917 | O11: 51 | P11: =IF(AND(G11>=2,M11>=80,L11<>"Below"),"Yes","No") -> No | Q11: Band 4 (Lead/Mgr) | R11: Active
A12: EMP0009 | B12: David Johnson | C12: Finance | D12: FP&A Manager | E12: Mid | F12: 2020-11-01 | G12: 5 | H12: 86500 | I12: =IF(L12="Outstanding",0.2,IF(L12="Exceeds",0.15,IF(L12="Meets",0.08,IF(L12="Below",0.02,0)))) -> 0.2 | J12: =H12*I12 -> 17300 | K12: =H12+J12 -> 103800 | L12: Outstanding | M12: 62.2 | N12: 0.936 | O12: 8 | P12: =IF(AND(G12>=2,M12>=80,L12<>"Below"),"Yes","No") -> No | Q12: =IF(H12<65000,"Band 1 (Junior)",IF(H12<90000,"Band 2 (Mid)",IF(H12<130000,"Band 3 (Senior)",IF(H12<170000,"Band 4 (Lead/Mgr)","Band 5 (Director)")))) -> Band 2 (Mid) | R12: Active
A13: EMP0010 | B13: Charles Wilson | C13: Product | D13: Head of Product | E13: Manager | F13: 2024-11-01 | G13: 1 | H13: 168600 | I13: =IF(L13="Outstanding",0.2,IF(L13="Exceeds",0.15,IF(L13="Meets",0.08,IF(L13="Below",0.02,0)))) -> 0.2 | J13: =H13*I13 -> 33720 | K13: =H13+J13 -> 202320 | L13: Outstanding | M13: 87.4 | N13: 0.936 | O13: 34 | P13: =IF(AND(G13>=2,M13>=80,L13<>"Below"),"Yes","No") -> No | Q13: =IF(H13<65000,"Band 1 (Junior)",IF(H13<90000,"Band 2 (Mid)",IF(H13<130000,"Band 3 (Senior)",IF(H13<170000,"Band 4 (Lead/Mgr)","Band 5 (Director)")))) -> Band 4 (Lead/Mgr) | R13: Probation
A14: EMP0011 | B14: Melissa Garcia | C14: Operations | D14: Process Manager | E14: Junior | F14: 2016-09-01 | G14: 9 | H14: 54100 | I14: =IF(L14="Outstanding",0.2,IF(L14="Exceeds",0.15,IF(L14="Meets",0.08,IF(L14="Below",0.02,0)))) -> 0.15 | J14: =H14*I14 -> 8115 | K14: =H14+J14 -> 62215 | L14: Exceeds | M14: 89.3 | N14: 0.902 | O14: 80 | P14: =IF(AND(G14>=2,M14>=80,L14<>"Below"),"Yes","No") -> Yes | Q14: =IF(H14<65000,"Band 1 (Junior)",IF(H14<90000,"Band 2 (Mid)",IF(H14<130000,"Band 3 (Senior)",IF(H14<170000,"Band 4 (Lead/Mgr)","Band 5 (Director)")))) -> Band 1 (Junior) | R14: Active
A15: EMP0012 | B15: Emily Lee | C15: Finance | D15: Controller | E15: Mid | F15: 2008-01-01 | G15: 17 | H15: 88800 | I15: =IF(L15="Outstanding",0.2,IF(L15="Exceeds",0.15,IF(L15="Meets",0.08,IF(L15="Below",0.02,0)))) -> 0.15 | J15: =H15*I15 -> 13320 | K15: =H15+J15 -> 102120 | L15: Exceeds | M15: 82 | N15: 0.898 | O15: 46 | P15: =IF(AND(G15>=2,M15>=80,L15<>"Below"),"Yes","No") -> Yes | Q15: =IF(H15<65000,"Band 1 (Junior)",IF(H15<90000,"Band 2 (Mid)",IF(H15<130000,"Band 3 (Senior)",IF(H15<170000,"Band 4 (Lead/Mgr)","Band 5 (Director)")))) -> Band 2 (Mid) | R15: Probation
A16: EMP0013 | B16: Jessica Moore | C16: HR | D16: HR Generalist | E16: Mid | F16: 2022-12-01 | G16: 3 | H16: 88700 | I16: =IF(L16="Outstanding",0.2,IF(L16="Exceeds",0.15,IF(L16="Meets",0.08,IF(L16="Below",0.02,0)))) -> 0.2 | J16: =H16*I16 -> 17740 | K16: =H16+J16 -> 106440 | L16: Outstanding | M16: 76.9 | N16: 0.814 | O16: 16 | P16: =IF(AND(G16>=2,M16>=80,L16<>"Below"),"Yes","No") -> No | Q16: =IF(H16<65000,"Band 1 (Junior)",IF(H16<90000,"Band 2 (Mid)",IF(H16<130000,"Band 3 (Senior)",IF(H16<170000,"Band 4 (Lead/Mgr)","Band 5 (Director)")))) -> Band 2 (Mid) | R16: Active
A17: EMP0014 | B17: William Thompson | C17: Legal | D17: Compliance Officer | E17: Manager | F17: 2011-04-01 | G17: 14 | H17: 163600 | I17: =IF(L17="Outstanding",0.2,IF(L17="Exceeds",0.15,IF(L17="Meets",0.08,IF(L17="Below",0.02,0)))) -> 0.08 | J17: =H17*I17 -> 13088 | K17: =H17+J17 -> 176688 | L17: Meets | M17: 96.8 | N17: 0.951 | O17: 39 | P17: =IF(AND(G17>=2,M17>=80,L17<>"Below"),"Yes","No") -> Yes | Q17: =IF(H17<65000,"Band 1 (Junior)",IF(H17<90000,"Band 2 (Mid)",IF(H17<130000,"Band 3 (Senior)",IF(H17<170000,"Band 4 (Lead/Mgr)","Band 5 (Director)")))) -> Band 4 (Lead/Mgr) | R17: Active
A18: EMP0015 | B18: Sarah Davis | C18: Operations | D18: COO | E18: Lead | F18: 2014-01-01 | G18: 11 | H18: 119000 | I18: =IF(L18="Outstanding",0.2,IF(L18="Exceeds",0.15,IF(L18="Meets",0.08,IF(L18="Below",0.02,0)))) -> 0.08 | J18: =H18*I18 -> 9520 | K18: =H18+J18 -> 128520 | L18: Meets | M18: 81.5 | N18: 0.846 | O18: 0 | P18: =IF(AND(G18>=2,M18>=80,L18<>"Below"),"Yes","No") -> Yes | Q18: Band 4 (Lead/Mgr) | R18: Active
A19: EMP0016 | B19: Maria Anderson | C19: Engineering | D19: Software Engineer | E19: Mid | F19: 2017-05-01 | G19: 8 | H19: 66800 | I19: =IF(L19="Outstanding",0.2,IF(L19="Exceeds",0.15,IF(L19="Meets",0.08,IF(L19="Below",0.02,0)))) -> 0.08 | J19: =H19*I19 -> 5344 | K19: =H19+J19 -> 72144 | L19: Meets | M19: 85.1 | N19: 0.843 | O19: 73 | P19: =IF(AND(G19>=2,M19>=80,L19<>"Below"),"Yes","No") -> Yes | Q19: =IF(H19<65000,"Band 1 (Junior)",IF(H19<90000,"Band 2 (Mid)",IF(H19<130000,"Band 3 (Senior)",IF(H19<170000,"Band 4 (Lead/Mgr)","Band 5 (Director)")))) -> Band 2 (Mid) | R19: Active
A20: EMP0017 | B20: Melissa Miller | C20: Legal | D20: CLO | E20: Mid | F20: 2011-06-01 | G20: 14 | H20: 67400 | I20: =IF(L20="Outstanding",0.2,IF(L20="Exceeds",0.15,IF(L20="Meets",0.08,IF(L20="Below",0.02,0)))) -> 0.15 | J20: =H20*I20 -> 10110 | K20: =H20+J20 -> 77510 | L20: Exceeds | M20: 74.1 | N20: 0.893 | O20: 12 | P20: =IF(AND(G20>=2,M20>=80,L20<>"Below"),"Yes","No") -> No | Q20: =IF(H20<65000,"Band 1 (Junior)",IF(H20<90000,"Band 2 (Mid)",IF(H20<130000,"Band 3 (Senior)",IF(H20<170000,"Band 4 (Lead/Mgr)","Band 5 (Director)")))) -> Band 2 (Mid) | R20: Active
A21: EMP0018 | B21: Sarah Davis | C21: Product | D21: Product Analyst | E21: Director | F21: 2007-08-01 | G21: 18 | H21: 163400 | I21: =IF(L21="Outstanding",0.2,IF(L21="Exceeds",0.15,IF(L21="Meets",0.08,IF(L21="Below",0.02,0)))) -> 0.02 | J21: =H21*I21 -> 3268 | K21: =H21+J21 -> 166668 | L21: Below | M21: 61.3 | N21: 0.837 | O21: 31 | P21: =IF(AND(G21>=2,M21>=80,L21<>"Below"),"Yes","No") -> No | Q21: =IF(H21<65000,"Band 1 (Junior)",IF(H21<90000,"Band 2 (Mid)",IF(H21<130000,"Band 3 (Senior)",IF(H21<170000,"Band 4 (Lead/Mgr)","Band 5 (Director)")))) -> Band 4 (Lead/Mgr) | R21: Probation
A22: EMP0019 | B22: Maria Lee | C22: Marketing | D22: Marketing Analyst | E22: Lead | F22: 2022-04-01 | G22: 3 | H22: 143400 | I22: =IF(L22="Outstanding",0.2,IF(L22="Exceeds",0.15,IF(L22="Meets",0.08,IF(L22="Below",0.02,0)))) -> 0.08 | J22: =H22*I22 -> 11472 | K22: =H22+J22 -> 154872 | L22: Meets | M22: 62.5 | N22: 0.897 | O22: 51 | P22: =IF(AND(G22>=2,M22>=80,L22<>"Below"),"Yes","No") -> No | Q22: =IF(H22<65000,"Band 1 (Junior)",IF(H22<90000,"Band 2 (Mid)",IF(H22<130000,"Band 3 (Senior)",IF(H22<170000,"Band 4 (Lead/Mgr)","Band 5 (Director)")))) -> Band 4 (Lead/Mgr) | R22: Active
A23: EMP0020 | B23: Richard Wilson | C23: Sales | D23: Account Executive | E23: Lead | F23: 2010-05-01 | G23: 15 | H23: 147100 | I23: =IF(L23="Outstanding",0.2,IF(L23="Exceeds",0.15,IF(L23="Meets",0.08,IF(L23="Below",0.02,0)))) -> 0.2 | J23: =H23*I23 -> 29420 | K23: =H23+J23 -> 176520 | L23: Outstanding | M23: 74 | N23: 0.991 | O23: 62 | P23: =IF(AND(G23>=2,M23>=80,L23<>"Below"),"Yes","No") -> No | Q23: =IF(H23<65000,"Band 1 (Junior)",IF(H23<90000,"Band 2 (Mid)",IF(H23<130000,"Band 3 (Senior)",IF(H23<170000,"Band 4 (Lead/Mgr)","Band 5 (Director)")))) -> Band 4 (Lead/Mgr) | R23: Active
A24: EMP0021 | B24: Maria Moore | C24: Finance | D24: Accountant | E24: Senior | F24: 2023-12-01 | G24: 2 | H24: 119400 | I24: =IF(L24="Outstanding",0.2,IF(L24="Exceeds",0.15,IF(L24="Meets",0.08,IF(L24="Below",0.02,0)))) -> 0.02 | J24: =H24*I24 -> 2388 | K24: =H24+J24 -> 121788 | L24: Below | M24: 69.1 | N24: 0.81 | O24: 64 | P24: =IF(AND(G24>=2,M24>=80,L24<>"Below"),"Yes","No") -> No | Q24: =IF(H24<65000,"Band 1 (Junior)",IF(H24<90000,"Band 2 (Mid)",IF(H24<130000,"Band 3 (Senior)",IF(H24<170000,"Band 4 (Lead/Mgr)","Band 5 (Director)")))) -> Band 3 (Senior) | R24: Probation
A25: EMP0022 | B25: Emily Williams | C25: Sales | D25: Account Executive | E25: Junior | F25: 2017-07-01 | G25: 8 | H25: 56900 | I25: =IF(L25="Outstanding",0.2,IF(L25="Exceeds",0.15,IF(L25="Meets",0.08,IF(L25="Below",0.02,0)))) -> 0.08 | J25: =H25*I25 -> 4552 | K25: =H25+J25 -> 61452 | L25: Meets | M25: 60.4 | N25: 0.978 | O25: 74 | P25: =IF(AND(G25>=2,M25>=80,L25<>"Below"),"Yes","No") -> No | Q25: =IF(H25<65000,"Band 1 (Junior)",IF(H25<90000,"Band 2 (Mid)",IF(H25<130000,"Band 3 (Senior)",IF(H25<170000,"Band 4 (Lead/Mgr)","Band 5 (Director)")))) -> Band 1 (Junior) | R25: Active
A26: EMP0023 | B26: Melissa Moore | C26: Engineering | D26: Software Engineer | E26: Manager | F26: 2014-05-01 | G26: 11 | H26: 148300 | I26: =IF(L26="Outstanding",0.2,IF(L26="Exceeds",0.15,IF(L26="Meets",0.08,IF(L26="Below",0.02,0)))) -> 0.08 | J26: =H26*I26 -> 11864 | K26: =H26+J26 -> 160164 | L26: Meets | M26: 64.2 | N26: 0.943 | O26: 33 | P26: =IF(AND(G26>=2,M26>=80,L26<>"Below"),"Yes","No") -> No | Q26: =IF(H26<65000,"Band 1 (Junior)",IF(H26<90000,"Band 2 (Mid)",IF(H26<130000,"Band 3 (Senior)",IF(H26<170000,"Band 4 (Lead/Mgr)","Band 5 (Director)")))) -> Band 4 (Lead/Mgr) | R26: Active
A27: EMP0024 | B27: Thomas Anderson | C27: Sales | D27: Business Dev Manager | E27: Director | F27: 2022-01-01 | G27: 3 | H27: 215000 | I27: =IF(L27="Outstanding",0.2,IF(L27="Exceeds",0.15,IF(L27="Meets",0.08,IF(L27="Below",0.02,0)))) -> 0.15 | J27: =H27*I27 -> 32250 | K27: =H27+J27 -> 247250 | L27: Exceeds | M27: 75.6 | N27: 1 | O27: 9 | P27: =IF(AND(G27>=2,M27>=80,L27<>"Below"),"Yes","No") -> No | Q27: =IF(H27<65000,"Band 1 (Junior)",IF(H27<90000,"Band 2 (Mid)",IF(H27<130000,"Band 3 (Senior)",IF(H27<170000,"Band 4 (Lead/Mgr)","Band 5 (Director)")))) -> Band 5 (Director) | R27: Active
A28: EMP0025 | B28: Michael Thomas | C28: Finance | D28: Controller | E28: Manager | F28: 2017-06-01 | G28: 8 | H28: 164000 | I28: =IF(L28="Outstanding",0.2,IF(L28="Exceeds",0.15,IF(L28="Meets",0.08,IF(L28="Below",0.02,0)))) -> 0.2 | J28: =H28*I28 -> 32800 | K28: =H28+J28 -> 196800 | L28: Outstanding | M28: 67.8 | N28: 0.888 | O28: 38 | P28: =IF(AND(G28>=2,M28>=80,L28<>"Below"),"Yes","No") -> No | Q28: =IF(H28<65000,"Band 1 (Junior)",IF(H28<90000,"Band 2 (Mid)",IF(H28<130000,"Band 3 (Senior)",IF(H28<170000,"Band 4 (Lead/Mgr)","Band 5 (Director)")))) -> Band 4 (Lead/Mgr) | R28: Active
A29: EMP0026 | B29: Sarah Jones | C29: Engineering | D29: QA Engineer | E29: Director | F29: 2021-12-01 | G29: 4 | H29: 168500 | I29: =IF(L29="Outstanding",0.2,IF(L29="Exceeds",0.15,IF(L29="Meets",0.08,IF(L29="Below",0.02,0)))) -> 0.2 | J29: =H29*I29 -> 33700 | K29: =H29+J29 -> 202200 | L29: Outstanding | M29: 79.9 | N29: 0.854 | O29: 26 | P29: =IF(AND(G29>=2,M29>=80,L29<>"Below"),"Yes","No") -> No | Q29: =IF(H29<65000,"Band 1 (Junior)",IF(H29<90000,"Band 2 (Mid)",IF(H29<130000,"Band 3 (Senior)",IF(H29<170000,"Band 4 (Lead/Mgr)","Band 5 (Director)")))) -> Band 4 (Lead/Mgr) | R29: On Leave
A30: EMP0027 | B30: Charles Martin | C30: Operations | D30: Process Manager | E30: Mid | F30: 2023-02-01 | G30: 2 | H30: 71300 | I30: =IF(L30="Outstanding",0.2,IF(L30="Exceeds",0.15,IF(L30="Meets",0.08,IF(L30="Below",0.02,0)))) -> 0.15 | J30: =H30*I30 -> 10695 | K30: =H30+J30 -> 81995 | L30: Exceeds | M30: 83.5 | N30: 0.966 | O30: 0 | P30: =IF(AND(G30>=2,M30>=80,L30<>"Below"),"Yes","No") -> Yes | Q30: =IF(H30<65000,"Band 1 (Junior)",IF(H30<90000,"Band 2 (Mid)",IF(H30<130000,"Band 3 (Senior)",IF(H30<170000,"Band 4 (Lead/Mgr)","Band 5 (Director)")))) -> Band 2 (Mid) | R30: Active
A31: EMP0028 | B31: Emily Harris | C31: Sales | D31: Business Dev Manager | E31: Director | F31: 2011-09-01 | G31: 14 | H31: 188600 | I31: =IF(L31="Outstanding",0.2,IF(L31="Exceeds",0.15,IF(L31="Meets",0.08,IF(L31="Below",0.02,0)))) -> 0.08 | J31: =H31*I31 -> 15088 | K31: =H31+J31 -> 203688 | L31: Meets | M31: 55.4 | N31: 0.815 | O31: 69 | P31: =IF(AND(G31>=2,M31>=80,L31<>"Below"),"Yes","No") -> No | Q31: =IF(H31<65000,"Band 1 (Junior)",IF(H31<90000,"Band 2 (Mid)",IF(H31<130000,"Band 3 (Senior)",IF(H31<170000,"Band 4 (Lead/Mgr)","Band 5 (Director)")))) -> Band 5 (Director) | R31: Active
A32: EMP0029 | B32: Melissa Jones | C32: Operations | D32: Logistics Coordinator | E32: Manager | F32: 2013-01-01 | G32: 12 | H32: 122100 | I32: =IF(L32="Outstanding",0.2,IF(L32="Exceeds",0.15,IF(L32="Meets",0.08,IF(L32="Below",0.02,0)))) -> 0.08 | J32: =H32*I32 -> 9768 | K32: =H32+J32 -> 131868 | L32: Meets | M32: 95.5 | N32: 0.842 | O32: 13 | P32: =IF(AND(G32>=2,M32>=80,L32<>"Below"),"Yes","No") -> Yes | Q32: Band 4 (Lead/Mgr) | R32: Active
A33: EMP0030 | B33: Jessica Garcia | C33: Product | D33: UX Designer | E33: Manager | F33: 2019-07-01 | G33: 6 | H33: 168800 | I33: =IF(L33="Outstanding",0.2,IF(L33="Exceeds",0.15,IF(L33="Meets",0.08,IF(L33="Below",0.02,0)))) -> 0.08 | J33: =H33*I33 -> 13504 | K33: =H33+J33 -> 182304 | L33: Meets | M33: 56.1 | N33: 0.947 | O33: 52 | P33: =IF(AND(G33>=2,M33>=80,L33<>"Below"),"Yes","No") -> No | Q33: =IF(H33<65000,"Band 1 (Junior)",IF(H33<90000,"Band 2 (Mid)",IF(H33<130000,"Band 3 (Senior)",IF(H33<170000,"Band 4 (Lead/Mgr)","Band 5 (Director)")))) -> Band 4 (Lead/Mgr) | R33: Probation
A34: EMP0031 | B34: Sarah Jackson | C34: Finance | D34: Accountant | E34: Senior | F34: 2009-04-01 | G34: 16 | H34: 124900 | I34: =IF(L34="Outstanding",0.2,IF(L34="Exceeds",0.15,IF(L34="Meets",0.08,IF(L34="Below",0.02,0)))) -> 0.08 | J34: =H34*I34 -> 9992 | K34: =H34+J34 -> 134892 | L34: Meets | M34: 64 | N34: 0.984 | O34: 39 | P34: =IF(AND(G34>=2,M34>=80,L34<>"Below"),"Yes","No") -> No | Q34: =IF(H34<65000,"Band 1 (Junior)",IF(H34<90000,"Band 2 (Mid)",IF(H34<130000,"Band 3 (Senior)",IF(H34<170000,"Band 4 (Lead/Mgr)","Band 5 (Director)")))) -> Band 3 (Senior) | R34: Probation
A35: EMP0032 | B35: Robert Jackson | C35: Finance | D35: Financial Analyst | E35: Mid | F35: 2022-05-01 | G35: 3 | H35: 73200 | I35: =IF(L35="Outstanding",0.2,IF(L35="Exceeds",0.15,IF(L35="Meets",0.08,IF(L35="Below",0.02,0)))) -> 0.2 | J35: =H35*I35 -> 14640 | K35: =H35+J35 -> 87840 | L35: Outstanding | M35: 70.8 | N35: 0.902 | O35: 42 | P35: =IF(AND(G35>=2,M35>=80,L35<>"Below"),"Yes","No") -> No | Q35: =IF(H35<65000,"Band 1 (Junior)",IF(H35<90000,"Band 2 (Mid)",IF(H35<130000,"Band 3 (Senior)",IF(H35<170000,"Band 4 (Lead/Mgr)","Band 5 (Director)")))) -> Band 2 (Mid) | R35: Active
A36: EMP0033 | B36: Daniel Wilson | C36: Marketing | D36: Brand Manager | E36: Senior | F36: 2005-07-01 | G36: 20 | H36: 91500 | I36: =IF(L36="Outstanding",0.2,IF(L36="Exceeds",0.15,IF(L36="Meets",0.08,IF(L36="Below",0.02,0)))) -> 0.02 | J36: =H36*I36 -> 1830 | K36: =H36+J36 -> 93330 | L36: Below | M36: 70.6 | N36: 0.957 | O36: 77 | P36: =IF(AND(G36>=2,M36>=80,L36<>"Below"),"Yes","No") -> No | Q36: =IF(H36<65000,"Band 1 (Junior)",IF(H36<90000,"Band 2 (Mid)",IF(H36<130000,"Band 3 (Senior)",IF(H36<170000,"Band 4 (Lead/Mgr)","Band 5 (Director)")))) -> Band 3 (Senior) | R36: Active
A37: EMP0034 | B37: William Johnson | C37: Marketing | D37: Brand Manager | E37: Lead | F37: 2024-09-01 | G37: 1 | H37: 138400 | I37: =IF(L37="Outstanding",0.2,IF(L37="Exceeds",0.15,IF(L37="Meets",0.08,IF(L37="Below",0.02,0)))) -> 0.08 | J37: =H37*I37 -> 11072 | K37: =H37+J37 -> 149472 | L37: Meets | M37: 96.7 | N37: 0.908 | O37: 46 | P37: =IF(AND(G37>=2,M37>=80,L37<>"Below"),"Yes","No") -> No | Q37: =IF(H37<65000,"Band 1 (Junior)",IF(H37<90000,"Band 2 (Mid)",IF(H37<130000,"Band 3 (Senior)",IF(H37<170000,"Band 4 (Lead/Mgr)","Band 5 (Director)")))) -> Band 4 (Lead/Mgr) | R37: Active
A38: EMP0035 | B38: Laura Anderson | C38: Marketing | D38: SEO Specialist | E38: Director | F38: 2021-12-01 | G38: 4 | H38: 196400 | I38: =IF(L38="Outstanding",0.2,IF(L38="Exceeds",0.15,IF(L38="Meets",0.08,IF(L38="Below",0.02,0)))) -> 0.02 | J38: =H38*I38 -> 3928 | K38: =H38+J38 -> 200328 | L38: Below | M38: 95.5 | N38: 0.901 | O38: 41 | P38: =IF(AND(G38>=2,M38>=80,L38<>"Below"),"Yes","No") -> No | Q38: =IF(H38<65000,"Band 1 (Junior)",IF(H38<90000,"Band 2 (Mid)",IF(H38<130000,"Band 3 (Senior)",IF(H38<170000,"Band 4 (Lead/Mgr)","Band 5 (Director)")))) -> Band 5 (Director) | R38: Active
A39: EMP0036 | B39: Robert White | C39: HR | D39: Recruiter | E39: Manager | F39: 2012-11-01 | G39: 13 | H39: 153200 | I39: =IF(L39="Outstanding",0.2,IF(L39="Exceeds",0.15,IF(L39="Meets",0.08,IF(L39="Below",0.02,0)))) -> 0.2 | J39: =H39*I39 -> 30640 | K39: =H39+J39 -> 183840 | L39: Outstanding | M39: 88.7 | N39: 0.835 | O39: 38 | P39: =IF(AND(G39>=2,M39>=80,L39<>"Below"),"Yes","No") -> Yes | Q39: =IF(H39<65000,"Band 1 (Junior)",IF(H39<90000,"Band 2 (Mid)",IF(H39<130000,"Band 3 (Senior)",IF(H39<170000,"Band 4 (Lead/Mgr)","Band 5 (Director)")))) -> Band 4 (Lead/Mgr) | R39: Active
A40: EMP0037 | B40: Robert White | C40: Engineering | D40: QA Engineer | E40: Senior | F40: 2005-11-01 | G40: 20 | H40: 121400 | I40: =IF(L40="Outstanding",0.2,IF(L40="Exceeds",0.15,IF(L40="Meets",0.08,IF(L40="Below",0.02,0)))) -> 0.08 | J40: =H40*I40 -> 9712 | K40: =H40+J40 -> 131112 | L40: Meets | M40: 69.5 | N40: 0.888 | O40: 65 | P40: =IF(AND(G40>=2,M40>=80,L40<>"Below"),"Yes","No") -> No | Q40: =IF(H40<65000,"Band 1 (Junior)",IF(H40<90000,"Band 2 (Mid)",IF(H40<130000,"Band 3 (Senior)",IF(H40<170000,"Band 4 (Lead/Mgr)","Band 5 (Director)")))) -> Band 3 (Senior) | R40: Active
...

Sheet Department Summary
A1: DEPARTMENT PERFORMANCE SUMMARY
A2: Auto-calculated from Employee Database | Use slicers/filters for drill-down
A3: Department | B3: Head Count | C3: Avg Base Salary | D3: Total Payroll | E3: Avg Bonus % | F3: Total Bonus | G3: Total Comp Cost | H3: Avg KPI Score | I3: Avg Attendance % | J3: Eligible for Promo
A4: Engineering | B4: =COUNTIF('Employee Database'!C4:C53,A4) -> 6 | C4: =AVERAGEIF('Employee Database'!C4:C53,A4,'Employee Database'!H4:H53) -> 112900 | D4: =SUMIF('Employee Database'!C4:C53,A4,'Employee Database'!H4:H53) -> 677400 | E4: =AVERAGEIF('Employee Database'!C4:C53,A4,'Employee Database'!I4:I53) -> 0.09 | F4: =SUMIF('Employee Database'!C4:C53,A4,'Employee Database'!J4:J53) -> 70992 | G4: =SUMIF('Employee Database'!C4:C53,A4,'Employee Database'!K4:K53) -> 748392 | H4: =AVERAGEIF('Employee Database'!C4:C53,A4,'Employee Database'!M4:M53) -> 73.866667 | I4: =AVERAGEIF('Employee Database'!C4:C53,A4,'Employee Database'!N4:N53) -> 0.89066667 | J4: =SUMPRODUCT(('Employee Database'!C4:C53=A4)*('Employee Database'!P4:P53="Yes")) -> 1
A5: Marketing | B5: =COUNTIF('Employee Database'!C4:C53,A5) -> 6 | C5: =AVERAGEIF('Employee Database'!C4:C53,A5,'Employee Database'!H4:H53) -> 130250 | D5: =SUMIF('Employee Database'!C4:C53,A5,'Employee Database'!H4:H53) -> 781500 | E5: =AVERAGEIF('Employee Database'!C4:C53,A5,'Employee Database'!I4:I53) -> 0.091666667 | F5: =SUMIF('Employee Database'!C4:C53,A5,'Employee Database'!J4:J53) -> 62462 | G5: =SUMIF('Employee Database'!C4:C53,A5,'Employee Database'!K4:K53) -> 843962 | H5: =AVERAGEIF('Employee Database'!C4:C53,A5,'Employee Database'!M4:M53) -> 79.25 | I5: =AVERAGEIF('Employee Database'!C4:C53,A5,'Employee Database'!N4:N53) -> 0.8995 | J5: =SUMPRODUCT(('Employee Database'!C4:C53=A5)*('Employee Database'!P4:P53="Yes")) -> 1
A6: Sales | B6: =COUNTIF('Employee Database'!C4:C53,A6) -> 5 | C6: =AVERAGEIF('Employee Database'!C4:C53,A6,'Employee Database'!H4:H53) -> 160820 | D6: =SUMIF('Employee Database'!C4:C53,A6,'Employee Database'!H4:H53) -> 804100 | E6: =AVERAGEIF('Employee Database'!C4:C53,A6,'Employee Database'!I4:I53) -> 0.118 | F6: =SUMIF('Employee Database'!C4:C53,A6,'Employee Database'!J4:J53) -> 97030 | G6: =SUMIF('Employee Database'!C4:C53,A6,'Employee Database'!K4:K53) -> 901130 | H6: =AVERAGEIF('Employee Database'!C4:C53,A6,'Employee Database'!M4:M53) -> 64.92 | I6: =AVERAGEIF('Employee Database'!C4:C53,A6,'Employee Database'!N4:N53) -> 0.9548 | J6: =SUMPRODUCT(('Employee Database'!C4:C53=A6)*('Employee Database'!P4:P53="Yes")) -> 0
A7: Finance | B7: =COUNTIF('Employee Database'!C4:C53,A7) -> 12 | C7: =AVERAGEIF('Employee Database'!C4:C53,A7,'Employee Database'!H4:H53) -> 114825 | D7: =SUMIF('Employee Database'!C4:C53,A7,'Employee Database'!H4:H53) -> 1377900 | E7: =AVERAGEIF('Employee Database'!C4:C53,A7,'Employee Database'!I4:I53) -> 0.13083333 | F7: =SUMIF('Employee Database'!C4:C53,A7,'Employee Database'!J4:J53) -> 174738 | G7: =SUMIF('Employee Database'!C4:C53,A7,'Employee Database'!K4:K53) -> 1552638 | H7: =AVERAGEIF('Employee Database'!C4:C53,A7,'Employee Database'!M4:M53) -> 70.7 | I7: =AVERAGEIF('Employee Database'!C4:C53,A7,'Employee Database'!N4:N53) -> 0.90341667 | J7: =SUMPRODUCT(('Employee Database'!C4:C53=A7)*('Employee Database'!P4:P53="Yes")) -> 1
A8: HR | B8: =COUNTIF('Employee Database'!C4:C53,A8) -> 5 | C8: =AVERAGEIF('Employee Database'!C4:C53,A8,'Employee Database'!H4:H53) -> 95580 | D8: =SUMIF('Employee Database'!C4:C53,A8,'Employee Database'!H4:H53) -> 477900 | E8: =AVERAGEIF('Employee Database'!C4:C53,A8,'Employee Database'!I4:I53) -> 0.14 | F8: =SUMIF('Employee Database'!C4:C53,A8,'Employee Database'!J4:J53) -> 67746 | G8: =SUMIF('Employee Database'!C4:C53,A8,'Employee Database'!K4:K53) -> 545646 | H8: =AVERAGEIF('Employee Database'!C4:C53,A8,'Employee Database'!M4:M53) -> 72.72 | I8: =AVERAGEIF('Employee Database'!C4:C53,A8,'Employee Database'!N4:N53) -> 0.8642 | J8: =SUMPRODUCT(('Employee Database'!C4:C53=A8)*('Employee Database'!P4:P53="Yes")) -> 1
A9: Operations | B9: =COUNTIF('Employee Database'!C4:C53,A9) -> 6 | C9: =AVERAGEIF('Employee Database'!C4:C53,A9,'Employee Database'!H4:H53) -> 104050 | D9: =SUMIF('Employee Database'!C4:C53,A9,'Employee Database'!H4:H53) -> 624300 | E9: =AVERAGEIF('Employee Database'!C4:C53,A9,'Employee Database'!I4:I53) -> 0.093333333 | F9: =SUMIF('Employee Database'!C4:C53,A9,'Employee Database'!J4:J53) -> 51858 | G9: =SUMIF('Employee Database'!C4:C53,A9,'Employee Database'!K4:K53) -> 676158 | H9: =AVERAGEIF('Employee Database'!C4:C53,A9,'Employee Database'!M4:M53) -> 87.716667 | I9: =AVERAGEIF('Employee Database'!C4:C53,A9,'Employee Database'!N4:N53) -> 0.8665 | J9: =SUMPRODUCT(('Employee Database'!C4:C53=A9)*('Employee Database'!P4:P53="Yes")) -> 5
A10: Product | B10: =COUNTIF('Employee Database'!C4:C53,A10) -> 6 | C10: =AVERAGEIF('Employee Database'!C4:C53,A10,'Employee Database'!H4:H53) -> 153266.67 | D10: =SUMIF('Employee Database'!C4:C53,A10,'Employee Database'!H4:H53) -> 919600 | E10: =AVERAGEIF('Employee Database'!C4:C53,A10,'Employee Database'!I4:I53) -> 0.12 | F10: =SUMIF('Employee Database'!C4:C53,A10,'Employee Database'!J4:J53) -> 108602 | G10: =SUMIF('Employee Database'!C4:C53,A10,'Employee Database'!K4:K53) -> 1028202 | H10: =AVERAGEIF('Employee Database'!C4:C53,A10,'Employee Database'!M4:M53) -> 75.15 | I10: =AVERAGEIF('Employee Database'!C4:C53,A10,'Employee Database'!N4:N53) -> 0.90483333 | J10: =SUMPRODUCT(('Employee Database'!C4:C53=A10)*('Employee Database'!P4:P53="Yes")) -> 1
A11: Legal | B11: =COUNTIF('Employee Database'!C4:C53,A11) -> 4 | C11: =AVERAGEIF('Employee Database'!C4:C53,A11,'Employee Database'!H4:H53) -> 134750 | D11: =SUMIF('Employee Database'!C4:C53,A11,'Employee Database'!H4:H53) -> 539000 | E11: =AVERAGEIF('Employee Database'!C4:C53,A11,'Employee Database'!I4:I53) -> 0.145 | F11: =SUMIF('Employee Database'!C4:C53,A11,'Employee Database'!J4:J53) -> 75178 | G11: =SUMIF('Employee Database'!C4:C53,A11,'Employee Database'!K4:K53) -> 614178 | H11: =AVERAGEIF('Employee Database'!C4:C53,A11,'Employee Database'!M4:M53) -> 84.025 | I11: =AVERAGEIF('Employee Database'!C4:C53,A11,'Employee Database'!N4:N53) -> 0.89575 | J11: =SUMPRODUCT(('Employee Database'!C4:C53=A11)*('Employee Database'!P4:P53="Yes")) -> 2
A12: TOTAL / AVERAGE | B12: =SUM(B4:B11) -> 50 | C12: =AVERAGE(C4:C11) -> 125805.21 | D12: =SUM(D4:D11) -> 6201700 | E12: =AVERAGE(E4:E11) -> 0.11610417 | F12: =SUM(F4:F11) -> 708606 | G12: =SUM(G4:G11) -> 6910306 | H12: =AVERAGE(H4:H11) -> 76.043542 | I12: =AVERAGE(I4:I11) -> 0.89745833 | J12: =SUM(J4:J11) -> 12
A14: Total Compensation Cost by Department

Sheet Performance Analytics
A1: PERFORMANCE ANALYTICS DASHBOARD
A3: Performance Rating Distribution | F3: Promotion Eligibility Pipeline
A4: Rating | B4: Count | C4: % of Total | D4: Avg KPI | F4: Level | G4: Total | H4: Eligible | I4: % Eligible | J4: Avg Salary
A5: Outstanding | B5: =COUNTIF('Employee Database'!L4:L53,A5) -> 16 | C5: =B5/50 -> 0.32 | D5: =AVERAGEIF('Employee Database'!L4:L53,A5,'Employee Database'!M4:M53) -> 76.75 | F5: Junior | G5: =COUNTIF('Employee Database'!E4:E53,F5) -> 8 | H5: =SUMPRODUCT(('Employee Database'!E4:E53=F5)*('Employee Database'!P4:P53="Yes")) -> 2 | I5: =IF(G5=0,0,H5/G5) -> 0.25 | J5: =AVERAGEIF('Employee Database'!E4:E53,F5,'Employee Database'!H4:H53) -> 55650
A6: Exceeds | B6: =COUNTIF('Employee Database'!L4:L53,A6) -> 7 | C6: =B6/50 -> 0.14 | D6: =AVERAGEIF('Employee Database'!L4:L53,A6,'Employee Database'!M4:M53) -> 80.685714 | F6: Mid | G6: =COUNTIF('Employee Database'!E4:E53,F6) -> 8 | H6: =SUMPRODUCT(('Employee Database'!E4:E53=F6)*('Employee Database'!P4:P53="Yes")) -> 3 | I6: =IF(G6=0,0,H6/G6) -> 0.375 | J6: =AVERAGEIF('Employee Database'!E4:E53,F6,'Employee Database'!H4:H53) -> 79037.5
A7: Meets | B7: =COUNTIF('Employee Database'!L4:L53,A7) -> 17 | C7: =B7/50 -> 0.34 | D7: =AVERAGEIF('Employee Database'!L4:L53,A7,'Employee Database'!M4:M53) -> 71.464706 | F7: Senior | G7: =COUNTIF('Employee Database'!E4:E53,F7) -> 6 | H7: =SUMPRODUCT(('Employee Database'!E4:E53=F7)*('Employee Database'!P4:P53="Yes")) -> 0 | I7: =IF(G7=0,0,H7/G7) -> 0 | J7: =AVERAGEIF('Employee Database'!E4:E53,F7,'Employee Database'!H4:H53) -> 112866.67
A8: Below | B8: =COUNTIF('Employee Database'!L4:L53,A8) -> 10 | C8: =B8/50 -> 0.2 | D8: =AVERAGEIF('Employee Database'!L4:L53,A8,'Employee Database'!M4:M53) -> 76.09 | F8: Lead | G8: =COUNTIF('Employee Database'!E4:E53,F8) -> 10 | H8: =SUMPRODUCT(('Employee Database'!E4:E53=F8)*('Employee Database'!P4:P53="Yes")) -> 3 | I8: =IF(G8=0,0,H8/G8) -> 0.3 | J8: =AVERAGEIF('Employee Database'!E4:E53,F8,'Employee Database'!H4:H53) -> 131950
A9: Total | B9: =SUM(B5:B8) -> 50 | C9: =SUM(C5:C8) -> 1 | D9: =AVERAGE('Employee Database'!M4:M53) -> 75.372 | F9: Manager | G9: =COUNTIF('Employee Database'!E4:E53,F9) -> 8 | H9: =SUMPRODUCT(('Employee Database'!E4:E53=F9)*('Employee Database'!P4:P53="Yes")) -> 3 | I9: =IF(G9=0,0,H9/G9) -> 0.375 | J9: =AVERAGEIF('Employee Database'!E4:E53,F9,'Employee Database'!H4:H53) -> 153887.5
F10: Director | G10: =COUNTIF('Employee Database'!E4:E53,F10) -> 10 | H10: =SUMPRODUCT(('Employee Database'!E4:E53=F10)*('Employee Database'!P4:P53="Yes")) -> 1 | I10: =IF(G10=0,0,H10/G10) -> 0.1 | J10: =AVERAGEIF('Employee Database'!E4:E53,F10,'Employee Database'!H4:H53) -> 189640
A12: KPI Threshold Breakdown
A13: KPI Range | B13: Employee Count | C13: % Share | D13: Avg Total Comp
A14: 90-100 (Top) | B14: =COUNTIF('Employee Database'!M4:M53,">=90") -> 7 | C14: =B14/50 -> 0.14 | D14: =AVERAGEIFS('Employee Database'!K4:K53,'Employee Database'!M4:M53,">=90") -> 178748.29
A15: 80-89 (Good) | B15: =COUNTIFS('Employee Database'!M4:M53,">=80",'Employee Database'!M4:M53,"<90") -> 12 | C15: =B15/50 -> 0.24 | D15: =AVERAGEIFS('Employee Database'!K4:K53,'Employee Database'!M4:M53,">=80",'Employee Database'!M4:M53,"<90") -> 115694.5
A16: 70-79 (Average) | B16: =COUNTIFS('Employee Database'!M4:M53,">=70",'Employee Database'!M4:M53,"<80") -> 9 | C16: =B16/50 -> 0.18 | D16: =AVERAGEIFS('Employee Database'!K4:K53,'Employee Database'!M4:M53,">=70",'Employee Database'!M4:M53,"<80") -> 130667.78
A17: Below 70 (At Risk) | B17: =COUNTIF('Employee Database'!M4:M53,"<70") -> 22 | C17: =B17/50 -> 0.44 | D17: =AVERAGEIFS('Employee Database'!K4:K53,'Employee Database'!M4:M53,"<70") -> 140669.27

Sheet Executive Dashboard
A1: EXECUTIVE HR DASHBOARD
A2: Real-time KPIs — Linked from source sheets | FY2025
A4: Total Employees | C4: Avg KPI Score | E4: Total Payroll | G4: Total Comp Cost
A5: =COUNTA('Employee Database'!A4:A53) -> 50 | C5: =AVERAGE('Employee Database'!M4:M53) -> 75.372 | E5: =SUM('Employee Database'!H4:H53) -> 6201700 | G5: =SUM('Employee Database'!K4:K53) -> 6910306
A10: Promo Eligible | C10: Avg Attendance % | E10: Outstanding Perf | G10: Avg Total Comp
A11: =COUNTIF('Employee Database'!P4:P53,"Yes") -> 12 | C11: =AVERAGE('Employee Database'!N4:N53) -> 0.89776 | E11: =COUNTIF('Employee Database'!L4:L53,"Outstanding") -> 16 | G11: =AVERAGE('Employee Database'!K4:K53) -> 138206.12
A17: Department Quick View
A18: Department | B18: Head Count | C18: Avg KPI | D18: Avg Attendance | E18: Total Comp | F18: Promo Count
A19: Engineering | B19: =COUNTIF('Employee Database'!C4:C53,A19) -> 6 | C19: =AVERAGEIF('Employee Database'!C4:C53,A19,'Employee Database'!M4:M53) -> 73.866667 | D19: =AVERAGEIF('Employee Database'!C4:C53,A19,'Employee Database'!N4:N53) -> 0.89066667 | E19: =SUMIF('Employee Database'!C4:C53,A19,'Employee Database'!K4:K53) -> 748392 | F19: =SUMPRODUCT(('Employee Database'!C4:C53=A19)*('Employee Database'!P4:P53="Yes")) -> 1
A20: Marketing | B20: =COUNTIF('Employee Database'!C4:C53,A20) -> 6 | C20: =AVERAGEIF('Employee Database'!C4:C53,A20,'Employee Database'!M4:M53) -> 79.25 | D20: =AVERAGEIF('Employee Database'!C4:C53,A20,'Employee Database'!N4:N53) -> 0.8995 | E20: =SUMIF('Employee Database'!C4:C53,A20,'Employee Database'!K4:K53) -> 843962 | F20: =SUMPRODUCT(('Employee Database'!C4:C53=A20)*('Employee Database'!P4:P53="Yes")) -> 1
A21: Sales | B21: =COUNTIF('Employee Database'!C4:C53,A21) -> 5 | C21: =AVERAGEIF('Employee Database'!C4:C53,A21,'Employee Database'!M4:M53) -> 64.92 | D21: =AVERAGEIF('Employee Database'!C4:C53,A21,'Employee Database'!N4:N53) -> 0.9548 | E21: =SUMIF('Employee Database'!C4:C53,A21,'Employee Database'!K4:K53) -> 901130 | F21: =SUMPRODUCT(('Employee Database'!C4:C53=A21)*('Employee Database'!P4:P53="Yes")) -> 0
A22: Finance | B22: =COUNTIF('Employee Database'!C4:C53,A22) -> 12 | C22: =AVERAGEIF('Employee Database'!C4:C53,A22,'Employee Database'!M4:M53) -> 70.7 | D22: =AVERAGEIF('Employee Database'!C4:C53,A22,'Employee Database'!N4:N53) -> 0.90341667 | E22: =SUMIF('Employee Database'!C4:C53,A22,'Employee Database'!K4:K53) -> 1552638 | F22: =SUMPRODUCT(('Employee Database'!C4:C53=A22)*('Employee Database'!P4:P53="Yes")) -> 1
A23: HR | B23: =COUNTIF('Employee Database'!C4:C53,A23) -> 5 | C23: =AVERAGEIF('Employee Database'!C4:C53,A23,'Employee Database'!M4:M53) -> 72.72 | D23: =AVERAGEIF('Employee Database'!C4:C53,A23,'Employee Database'!N4:N53) -> 0.8642 | E23: =SUMIF('Employee Database'!C4:C53,A23,'Employee Database'!K4:K53) -> 545646 | F23: =SUMPRODUCT(('Employee Database'!C4:C53=A23)*('Employee Database'!P4:P53="Yes")) -> 1
A24: Operations | B24: =COUNTIF('Employee Database'!C4:C53,A24) -> 6 | C24: =AVERAGEIF('Employee Database'!C4:C53,A24,'Employee Database'!M4:M53) -> 87.716667 | D24: =AVERAGEIF('Employee Database'!C4:C53,A24,'Employee Database'!N4:N53) -> 0.8665 | E24: =SUMIF('Employee Database'!C4:C53,A24,'Employee Database'!K4:K53) -> 676158 | F24: =SUMPRODUCT(('Employee Database'!C4:C53=A24)*('Employee Database'!P4:P53="Yes")) -> 5
A25: Product | B25: =COUNTIF('Employee Database'!C4:C53,A25) -> 6 | C25: =AVERAGEIF('Employee Database'!C4:C53,A25,'Employee Database'!M4:M53) -> 75.15 | D25: =AVERAGEIF('Employee Database'!C4:C53,A25,'Employee Database'!N4:N53) -> 0.90483333 | E25: =SUMIF('Employee Database'!C4:C53,A25,'Employee Database'!K4:K53) -> 1028202 | F25: =SUMPRODUCT(('Employee Database'!C4:C53=A25)*('Employee Database'!P4:P53="Yes")) -> 1
A26: Legal | B26: =COUNTIF('Employee Database'!C4:C53,A26) -> 4 | C26: =AVERAGEIF('Employee Database'!C4:C53,A26,'Employee Database'!M4:M53) -> 84.025 | D26: =AVERAGEIF('Employee Database'!C4:C53,A26,'Employee Database'!N4:N53) -> 0.89575 | E26: =SUMIF('Employee Database'!C4:C53,A26,'Employee Database'!K4:K53) -> 614178 | F26: =SUMPRODUCT(('Employee Database'!C4:C53=A26)*('Employee Database'!P4:P53="Yes")) -> 2

Sheet Salary Analysis
A1: COMPENSATION & SALARY ANALYSIS
A3: Salary Statistics by Level
A4: Level | B4: Count | C4: Min Salary | D4: Max Salary | E4: Avg Salary | F4: Median (Approx) | G4: Std Dev | H4: Total Cost
A5: Junior | B5: =COUNTIF('Employee Database'!E4:E53,A5) -> 8 | C5: 47800 | D5: 64500 | E5: =AVERAGEIF('Employee Database'!E4:E53,A5,'Employee Database'!H4:H53) -> 55650 | F5: 56400 | G5: 5054.84 | H5: =SUMIF('Employee Database'!E4:E53,A5,'Employee Database'!K4:K53) -> 497863
A6: Mid | B6: =COUNTIF('Employee Database'!E4:E53,A6) -> 8 | C6: 66800 | D6: 89600 | E6: =AVERAGEIF('Employee Database'!E4:E53,A6,'Employee Database'!H4:H53) -> 79037.5 | F6: 79850 | G6: 10247.36 | H6: =SUMIF('Employee Database'!E4:E53,A6,'Employee Database'!K4:K53) -> 739369
A7: Senior | B7: =COUNTIF('Employee Database'!E4:E53,A7) -> 6 | C7: 91500 | D7: 124900 | E7: =AVERAGEIF('Employee Database'!E4:E53,A7,'Employee Database'!H4:H53) -> 112866.67 | F7: 116900 | G7: 12425.73 | H7: =SUMIF('Employee Database'!E4:E53,A7,'Employee Database'!K4:K53) -> 711858
A8: Lead | B8: =COUNTIF('Employee Database'!E4:E53,A8) -> 10 | C8: 115400 | D8: 147100 | E8: =AVERAGEIF('Employee Database'!E4:E53,A8,'Employee Database'!H4:H53) -> 131950 | F8: 137300 | G8: 12687.9 | H8: =SUMIF('Employee Database'!E4:E53,A8,'Employee Database'!K4:K53) -> 1482486
A9: Manager | B9: =COUNTIF('Employee Database'!E4:E53,A9) -> 8 | C9: 122100 | D9: 168800 | E9: =AVERAGEIF('Employee Database'!E4:E53,A9,'Employee Database'!H4:H53) -> 153887.5 | F9: 158400 | G9: 16067.93 | H9: =SUMIF('Employee Database'!E4:E53,A9,'Employee Database'!K4:K53) -> 1379334
A10: Director | B10: =COUNTIF('Employee Database'!E4:E53,A10) -> 10 | C10: 163400 | D10: 215000 | E10: =AVERAGEIF('Employee Database'!E4:E53,A10,'Employee Database'!H4:H53) -> 189640 | F10: 194400 | G10: 18455.66 | H10: =SUMIF('Employee Database'!E4:E53,A10,'Employee Database'!K4:K53) -> 2099396
A11: Company Total | B11: =SUM(B5:B10) -> 50 | C11: =MIN('Employee Database'!H4:H53) -> 47800 | D11: =MAX('Employee Database'!H4:H53) -> 215000 | E11: =AVERAGE('Employee Database'!H4:H53) -> 124034 | F11: =(C11+D11)/2 -> 131400 | G11: =STDEV('Employee Database'!H4:H53) -> 48056.551 | H11: =SUM('Employee Database'!K4:K53) -> 6910306
A14: Salary Band Distribution
A15: Band | B15: Range | C15: Employee Count | D15: % of Workforce | E15: Avg KPI | F15: Avg Attendance | G15: Avg Total Comp | H15: Promo Eligible
A16: Band 1 (Junior) | B16: <$65K | C16: =COUNTIF('Employee Database'!Q4:Q53,A16) -> 8 | D16: =C16/50 -> 0.16 | E16: =AVERAGEIF('Employee Database'!Q4:Q53,A16,'Employee Database'!M4:M53) -> 74.775 | F16: =AVERAGEIF('Employee Database'!Q4:Q53,A16,'Employee Database'!N4:N53) -> 0.92575 | G16: =AVERAGEIF('Employee Database'!Q4:Q53,A16,'Employee Database'!K4:K53) -> 62232.875 | H16: =SUMPRODUCT(('Employee Database'!Q4:Q53=A16)*('Employee Database'!P4:P53="Yes")) -> 2
A17: Band 2 (Mid) | B17: $65K-$90K | C17: =COUNTIF('Employee Database'!Q4:Q53,A17) -> 8 | D17: =C17/50 -> 0.16 | E17: =AVERAGEIF('Employee Database'!Q4:Q53,A17,'Employee Database'!M4:M53) -> 76.2625 | F17: =AVERAGEIF('Employee Database'!Q4:Q53,A17,'Employee Database'!N4:N53) -> 0.903625 | G17: =AVERAGEIF('Employee Database'!Q4:Q53,A17,'Employee Database'!K4:K53) -> 92421.125 | H17: =SUMPRODUCT(('Employee Database'!Q4:Q53=A17)*('Employee Database'!P4:P53="Yes")) -> 3
A18: Band 3 (Senior) | B18: $90K-$130K | C18: =COUNTIF('Employee Database'!Q4:Q53,A18) -> 6 | D18: =C18/50 -> 0.12 | E18: =AVERAGEIF('Employee Database'!Q4:Q53,A18,'Employee Database'!M4:M53) -> 70.566667 | F18: =AVERAGEIF('Employee Database'!Q4:Q53,A18,'Employee Database'!N4:N53) -> 0.89416667 | G18: =AVERAGEIF('Employee Database'!Q4:Q53,A18,'Employee Database'!K4:K53) -> 118643 | H18: =SUMPRODUCT(('Employee Database'!Q4:Q53=A18)*('Employee Database'!P4:P53="Yes")) -> 0
A19: Band 4 (Lead/Mgr) | B19: $130K-$170K | C19: =COUNTIF('Employee Database'!Q4:Q53,A19) -> 21 | D19: =C19/50 -> 0.42 | E19: =AVERAGEIF('Employee Database'!Q4:Q53,A19,'Employee Database'!M4:M53) -> 75.8 | F19: =AVERAGEIF('Employee Database'!Q4:Q53,A19,'Employee Database'!N4:N53) -> 0.88771429 | G19: =AVERAGEIF('Employee Database'!Q4:Q53,A19,'Employee Database'!K4:K53) -> 162823.24 | H19: =SUMPRODUCT(('Employee Database'!Q4:Q53=A19)*('Employee Database'!P4:P53="Yes")) -> 6
A20: Band 5 (Director) | B20: $170K+ | C20: =COUNTIF('Employee Database'!Q4:Q53,A20) -> 7 | D20: =C20/50 -> 0.14 | E20: =AVERAGEIF('Employee Database'!Q4:Q53,A20,'Employee Database'!M4:M53) -> 77.871429 | F20: =AVERAGEIF('Employee Database'!Q4:Q53,A20,'Employee Database'!N4:N53) -> 0.89228571 | G20: =AVERAGEIF('Employee Database'!Q4:Q53,A20,'Employee Database'!K4:K53) -> 220275.43 | H20: =SUMPRODUCT(('Employee Database'!Q4:Q53=A20)*('Employee Database'!P4:P53="Yes")) -> 1
